<?xml version="1.0" encoding="utf-8"?>
<mujoco model="cabinet_large">
  <worldbody>
      <body>
        <body name="object" pos="0.3 0 0">
	  <body name="base" pos="0 0 0" quat="1 0 0 0">
	    
            <geom material="MatRedWood" pos="-0.11 0 0.065" size="0.008 0.2 0.065" group="1" type="box" mass=".05"/>
            <geom material="MatRedWood" pos="0.11 0 0.065" size="0.008 0.2 0.065" group="1" type="box" mass=".05"/>
            <geom material="MatRedWood" pos="0 0.196 0.065" size="0.106 0.008 0.065" group="1" type="box" mass=".05"/>
            <geom material="MatRedWood" pos="0 0 0.004" size="0.118 0.2 0.008" group="1" type="box" mass=".05"/>
            <geom material="MatRedWood" pos="0 0.01 0.124" size="0.11 0.19 0.008" group="1" type="box" mass=".05"/>
            <geom material="MatRedWood" pos="-0.103 -0.19 0.065" size="0.012 0.01 0.065" group="1" type="box" mass=".05"/>
            <geom material="MatRedWood" pos="0.103 -0.19 0.065" size="0.012 0.01 0.065" group="1" type="box" mass=".05"/>

	    <body name="drawer_link" pos="0 -0.01 0.076">
              <inertial pos="0 0 0.35" quat="0.5 0.5 0.5 0.5" mass="7.85398" diaginertia="0.923301 0.764585 0.168533" />
	      
	      <joint type="slide" range="-0.4 0" axis="0 1 0"
		     name="goal_slidey" pos="0 0 0" damping="50.0"/>
                <geom material="MatRedWood" pos="0 -0.185 0.0068" size="0.09 0.010 0.056" group="1" type="box" mass=".04"/>
                <geom material="MatRedWood" pos="0 0.153 0.008" size="0.095 0.008 0.028" group="1" type="box" mass=".04"/>
                <geom material="MatRedWood" pos="-0.072 -0.015 0.00" size="0.008 0.165 0.028" group="1" type="box" mass=".04"/>
                <geom material="MatRedWood" pos="0.072 -0.015 0.00" size="0.008 0.165 0.028" group="1" type="box" mass=".04"/>
                <geom material="MatRedWood" pos="0 -0.005 -0.04" size="0.08 0.175 0.008" group="1" type="box" mass=".04"/>
                <geom material="MatCeramic" euler="1.571 0 0" pos="-0.05 -0.218 0.04" size="0.009 0.03" group="1" type="capsule" mass=".06"/>
                <geom material="MatCeramic" euler="0 1.57 0" pos="0 -0.248 0.04" size="0.009 0.05" group="1" type="capsule" mass=".06"/>
                <geom material="MatCeramic" euler="1.57 0 0" pos="0.05 -0.218 0.04" size="0.009 0.03" group="1" type="capsule" mass=".06"/>
        <site name="handle_site" pos="0 -0.16 0.04" rgba="0 0 1 0.5" size="0.02" type="sphere"/>
	    </body>
          </body>
        </body>
        <site name="bottom_site" pos="0 0 -0.3" rgba="0 0 0 0" size="0.005"/>
        <site name="top_site" pos="0 0 0.3" rgba="0 0 0 0" size="0.005"/>
        <site name="horizontal_radius_site" pos="0.3 0 0" rgba="0 0 0 0" size="0.1"/>
      </body>
    </worldbody>
</mujoco>
